<sdf version="1.5">
  <model name="human" xmlns:xacro="http://www.ros.org/wiki/xacro">
   <xacro:property name="armEffort" value="30" /> <!-- Standard value is 30 -->
   <xacro:property name="wristEffort" value="10" /> <!-- Standard value is 10 -->
   <xacro:property name="jointFriction" value="0" />
   <xacro:include filename="../pr2/pr2.include" />

   <!-- Add a weight to the pr2 arm -->
    <link name='weight'>
       <!-- Pose of end of r_wrist_roll_link -->
       <pose>0.84791 -0.188 0.790675 0.0 0.0 0.0</pose>

       <inertial>
          <mass>1.8</mass> <!-- Max design support weight of arm -->
          <pose>0.0 0.0 0.0 0.0 0.0 0.0</pose><!-- Link mass is centered -->
       </inertial>
       <collision name='collision'>
          <geometry>
             <box>
                <size>0.01 0.01 0.01</size>
             </box>
          </geometry>
       </collision>
       <visual name='visual'>
          <geometry>
             <box>
                <size>0.1 0.1 0.1</size>
             </box>
          </geometry>
       </visual>
       <self_collide>0</self_collide>
    </link>
   <joint name='weight_connector' type='revolute'>
     <parent>r_wrist_roll_link</parent>
     <child>weight</child>
     <axis>
        <xyz>0.0 1 0.0</xyz>
      </axis>
   </joint>

   <plugin name="calibration_plugin" filename="libArmCalibrationPlugin.dylib"/>  
   <plugin name="joint_forces_plugin" filename="libJointForcesPlugin.dylib"/>

   <plugin name="pr2_arm_controller" filename="libStableControllerPlugin.dylib">
      <control-delay>0</control-delay>
      <controlled-joint>r_shoulder_lift_joint</controlled-joint>
      <controlled-joint>r_shoulder_pan_joint</controlled-joint>
      <controlled-joint>r_upper_arm_roll_joint</controlled-joint>
      <controlled-joint>r_elbow_flex_joint</controlled-joint>
      <controlled-joint>r_forearm_roll_joint</controlled-joint>
      <controlled-joint>r_wrist_flex_joint</controlled-joint>
      <controlled-joint>r_wrist_roll_joint</controlled-joint>
      <controlled-joint>l_shoulder_lift_joint</controlled-joint>
      <controlled-joint>l_shoulder_pan_joint</controlled-joint>
      <controlled-joint>l_upper_arm_roll_joint</controlled-joint>
      <controlled-joint>l_elbow_flex_joint</controlled-joint>
      <controlled-joint>l_forearm_roll_joint</controlled-joint>
      <controlled-joint>l_wrist_flex_joint</controlled-joint>
      <controlled-joint>l_wrist_roll_joint</controlled-joint>
   </plugin>
  </model>
</sdf>
